Workbook

Sheet quick_qr
A1: Techcombank | B1: =HYPERLINK(VLOOKUP($A$1,TaiKhoan!$C:$J,8,0)&$A$2, "vietqr_link") -> vietqr_link | C1: GRAB | D1: =HYPERLINK(VLOOKUP(C1,MauChuyenTien!$A:$G,7,0),"vietqr_link") -> vietqr_link
A2: 10000
A3: =IMAGE(VLOOKUP($A$1,TaiKhoan!$C:$J,8,0)&$A$2) | C3: data__bin | D3: =VLOOKUP($A$1,TaiKhoan!C:H,6,0) -> 970407
C4: data__short_name | D4: =VLOOKUP($A$1,TaiKhoan!C:H,5,0) -> Techcombank
C5: data_num | D5: =VLOOKUP($A$1,TaiKhoan!C:H,3,0) -> 44699999999
C6: name_ac | D6: =VLOOKUP($A$1,TaiKhoan!C:H,2,0) -> Huynh Tran Tuan Kiet

Sheet TaiKhoan
A1: stt | B1: id | C1: list_name | D1: name_ac | E1: data_num | F1: data__code | G1: data__short_name | H1: data__bin | I1: data__logo | J1: vietqr_link | K1: hidden | L1: isDefault
A2: 1 | B2: 43 | C2: Vietcombank | D2: Huynh Tran Tuan Kiet | E2: 1031451081 | F2: =IFERROR(VLOOKUP(B2,Banks!$A:$F,3),"") -> VCB | G2: =IFERROR(VLOOKUP(B2,Banks!$A:$F,5),"") -> Vietcombank | H2: =IFERROR(VLOOKUP(B2,Banks!$A:$F,4),"") -> 970436 | I2: =IFERROR(VLOOKUP(B2,Banks!$A:$F,6),"") -> https://cdn.vietqr.io/img/VCB.png | J2: =IFERROR(__xludf.DUMMYFUNCTION("""https://img.vietqr.io/image/""&F2&""-""&E2&""-""&FILTER(MauHienThi!$A:$A,MauHienThi!$C:$C=TRUE)&"".png?accountName=""&ENCODEURL(D2)&""&amount="""),"https://img.vietqr.io/image/VCB-1031451081-compact2.png?accountName=Huynh%20Tran%20Tuan%20Kiet&amount=") -> https://img.vietqr.io/image/VCB-1031451081-compact2.png?accountName=Huynh%20Tran%20Tuan%20Kiet&amount= | K2: FALSE | L2: TRUE
A3: 2 | B3: 38 | C3: Techcombank | D3: Huynh Tran Tuan Kiet | E3: 44699999999 | F3: =IFERROR(VLOOKUP(B3,Banks!$A:$F,3),"") -> TCB | G3: =IFERROR(VLOOKUP(B3,Banks!$A:$F,5),"") -> Techcombank | H3: =IFERROR(VLOOKUP(B3,Banks!$A:$F,4),"") -> 970407 | I3: https://cdn.vietqr.io/img/TCB.png | J3: =IFERROR(__xludf.DUMMYFUNCTION("""https://img.vietqr.io/image/""&F3&""-""&E3&""-""&FILTER(MauHienThi!$A:$A,MauHienThi!$C:$C=TRUE)&"".png?accountName=""&ENCODEURL(D3)&""&amount="""),"https://img.vietqr.io/image/TCB-44699999999-compact2.png?accountName=Huynh%20Tran%20Tuan%20Kiet&amount=") -> https://img.vietqr.io/image/TCB-44699999999-compact2.png?accountName=Huynh%20Tran%20Tuan%20Kiet&amount= | K3: FALSE | L3: FALSE
A4: 3 | B4: 21 | C4: Viettel Money | D4: Huynh Tran Tuan Kiet | E4: 9704229201938102578 | F4: =IFERROR(VLOOKUP(B4,Banks!$A:$F,3),"") -> MB | G4: =IFERROR(VLOOKUP(B4,Banks!$A:$F,5),"") -> MBBank | H4: =IFERROR(VLOOKUP(B4,Banks!$A:$F,4),"") -> 970422 | I4: https://cdn.vietqr.io/img/MB.png | J4: =IFERROR(__xludf.DUMMYFUNCTION("""https://img.vietqr.io/image/""&F4&""-""&E4&""-""&FILTER(MauHienThi!$A:$A,MauHienThi!$C:$C=TRUE)&"".png?accountName=""&ENCODEURL(D4)&""&amount="""),"https://img.vietqr.io/image/MB-9704229201938102578-compact2.png?accountName=Huynh%20Tran%20Tuan%20Kiet&amount=") -> https://img.vietqr.io/image/MB-9704229201938102578-compact2.png?accountName=Huynh%20Tran%20Tuan%20Kiet&amount= | K4: FALSE | L4: FALSE
A5: 4 | B5: 17 | C5: Duy Khoi - ICB | D5: Phan Le Duy Khoi | E5: 105878043349 | F5: =IFERROR(VLOOKUP(B5,Banks!$A:$F,3),"") -> ICB | G5: =IFERROR(VLOOKUP(B5,Banks!$A:$F,5),"") -> VietinBank | H5: =IFERROR(VLOOKUP(B5,Banks!$A:$F,4),"") -> 970415 | I5: https://cdn.vietqr.io/img/ICB.png | J5: =IFERROR(__xludf.DUMMYFUNCTION("""https://img.vietqr.io/image/""&F5&""-""&E5&""-""&FILTER(MauHienThi!$A:$A,MauHienThi!$C:$C=TRUE)&"".png?accountName=""&ENCODEURL(D5)&""&amount="""),"https://img.vietqr.io/image/ICB-105878043349-compact2.png?accountName=Phan%20Le%20Duy%20Khoi&amount=") -> https://img.vietqr.io/image/ICB-105878043349-compact2.png?accountName=Phan%20Le%20Duy%20Khoi&amount= | K5: FALSE | L5: FALSE
A6: 5 | B6: 43 | C6: SHOPEE PAY | D6: ShopeePay HUYNH TRAN TUAN KIET | E6: SPAY126223392538231 | F6: =IFERROR(VLOOKUP(B6,Banks!$A:$F,3),"") -> VCB | G6: =IFERROR(VLOOKUP(B6,Banks!$A:$F,5),"") -> Vietcombank | H6: =IFERROR(VLOOKUP(B6,Banks!$A:$F,4),"") -> 970436 | I6: https://cdn.vietqr.io/img/VCB.png | J6: =IFERROR(__xludf.DUMMYFUNCTION("""https://img.vietqr.io/image/""&F6&""-""&E6&""-""&FILTER(MauHienThi!$A:$A,MauHienThi!$C:$C=TRUE)&"".png?accountName=""&ENCODEURL(D6)&""&amount="""),"https://img.vietqr.io/image/VCB-SPAY126223392538231-compact2.png?accountName=ShopeePay%20%20HUYNH%20TRAN%20TUAN%20KIET&amount=") -> https://img.vietqr.io/image/VCB-SPAY126223392538231-compact2.png?accountName=ShopeePay%20%20HUYNH%20TRAN%20TUAN%20KIET&amount= | K6: FALSE | L6: FALSE
A7: 6 | B7: 65 | C7: MOMO0396105653 | D7: Huynh Tran Tuan Kiet | E7: PSP2605516100000204 | F7: =IFERROR(VLOOKUP(B7,Banks!$A:$F,3),"") -> momo | G7: =IFERROR(VLOOKUP(B7,Banks!$A:$F,5),"") -> MoMo | H7: =IFERROR(VLOOKUP(B7,Banks!$A:$F,4),"") -> 971025 | I7: https://cdn.vietqr.io/img/momo.png | J7: =IFERROR(__xludf.DUMMYFUNCTION("""https://img.vietqr.io/image/""&F7&""-""&E7&""-""&FILTER(MauHienThi!$A:$A,MauHienThi!$C:$C=TRUE)&"".png?accountName=""&ENCODEURL(D7)&""&amount="""),"https://img.vietqr.io/image/momo-PSP2605516100000204-compact2.png?accountName=Huynh%20Tran%20Tuan%20Kiet&amount=") -> https://img.vietqr.io/image/momo-PSP2605516100000204-compact2.png?accountName=Huynh%20Tran%20Tuan%20Kiet&amount= | K7: FALSE | L7: FALSE
A8: 7 | B8: 17 | C8: GRAB | D8: CONG TY TNHH GRAB | E8: 150010000111 | F8: =IFERROR(VLOOKUP(B8,Banks!$A:$F,3),"") -> ICB | G8: =IFERROR(VLOOKUP(B8,Banks!$A:$F,5),"") -> VietinBank | H8: =IFERROR(VLOOKUP(B8,Banks!$A:$F,4),"") -> 970415 | I8: https://cdn.vietqr.io/img/ICB.png | J8: =IFERROR(__xludf.DUMMYFUNCTION("""https://img.vietqr.io/image/""&F8&""-""&E8&""-""&FILTER(MauHienThi!$A:$A,MauHienThi!$C:$C=TRUE)&"".png?accountName=""&ENCODEURL(D8)&""&amount="""),"https://img.vietqr.io/image/ICB-150010000111-compact2.png?accountName=CONG%20TY%20TNHH%20GRAB&amount=") -> https://img.vietqr.io/image/ICB-150010000111-compact2.png?accountName=CONG%20TY%20TNHH%20GRAB&amount= | K8: FALSE | L8: FALSE
A9: 8 | B9: 47 | C9: VP BANK | D9: Huynh Tran Tuan Kiet | E9: 4681010052004 | F9: =IFERROR(VLOOKUP(B9,Banks!$A:$F,3),"") -> VPB | G9: =IFERROR(VLOOKUP(B9,Banks!$A:$F,5),"") -> VPBank | H9: =IFERROR(VLOOKUP(B9,Banks!$A:$F,4),"") -> 970432 | I9: https://cdn.vietqr.io/img/VPB.png | J9: =IFERROR(__xludf.DUMMYFUNCTION("""https://img.vietqr.io/image/""&F9&""-""&E9&""-""&FILTER(MauHienThi!$A:$A,MauHienThi!$C:$C=TRUE)&"".png?accountName=""&ENCODEURL(D9)&""&amount="""),"https://img.vietqr.io/image/VPB-4681010052004-compact2.png?accountName=Huynh%20Tran%20Tuan%20Kiet&amount=") -> https://img.vietqr.io/image/VPB-4681010052004-compact2.png?accountName=Huynh%20Tran%20Tuan%20Kiet&amount= | K9: FALSE | L9: FALSE
A10: 9 | B10: 45 | C10: VIB - 052004 | D10: HUYNH TRAN TUAN KIET | E10: 052004 | F10: =IFERROR(VLOOKUP(B10,Banks!$A:$F,3),"") -> VIB | G10: =IFERROR(VLOOKUP(B10,Banks!$A:$F,5),"") -> VIB | H10: =IFERROR(VLOOKUP(B10,Banks!$A:$F,4),"") -> 970441 | I10: https://cdn.vietqr.io/img/VIB.png | J10: =IFERROR(__xludf.DUMMYFUNCTION("""https://img.vietqr.io/image/""&F10&""-""&E10&""-""&FILTER(MauHienThi!$A:$A,MauHienThi!$C:$C=TRUE)&"".png?accountName=""&ENCODEURL(D10)&""&amount="""),"https://img.vietqr.io/image/VIB-052004-compact2.png?accountName=HUYNH%20TRAN%20TUAN%20KIET&amount=") -> https://img.vietqr.io/image/VIB-052004-compact2.png?accountName=HUYNH%20TRAN%20TUAN%20KIET&amount= | K10: FALSE | L10: FALSE
A11: 10 | B11: 65 | C11: MOMO _ 0899982103 | D11: Huynh Tran Tuan Kiet | E11: PSP2623411000000071 | F11: =IFERROR(VLOOKUP(B11,Banks!$A:$F,3),"") -> momo | G11: =IFERROR(VLOOKUP(B11,Banks!$A:$F,5),"") -> MoMo | H11: =IFERROR(VLOOKUP(B11,Banks!$A:$F,4),"") -> 971025 | I11: https://cdn.vietqr.io/img/momo.png | J11: =IFERROR(__xludf.DUMMYFUNCTION("""https://img.vietqr.io/image/""&F11&""-""&E11&""-""&FILTER(MauHienThi!$A:$A,MauHienThi!$C:$C=TRUE)&"".png?accountName=""&ENCODEURL(D11)&""&amount="""),"https://img.vietqr.io/image/momo-PSP2623411000000071-compact2.png?accountName=Huynh%20Tran%20Tuan%20Kiet&amount=") -> https://img.vietqr.io/image/momo-PSP2623411000000071-compact2.png?accountName=Huynh%20Tran%20Tuan%20Kiet&amount= | K11: FALSE | L11: FALSE
A12: 11 | B12: 47 | C12: TTT - MOMO | D12: MoMo - TKTH Huynh Tran Tuan Kiet | E12: 01MMTTT0075996061 | F12: =IFERROR(VLOOKUP(B12,Banks!$A:$F,3),"") -> VPB | G12: =IFERROR(VLOOKUP(B12,Banks!$A:$F,5),"") -> VPBank | H12: =IFERROR(VLOOKUP(B12,Banks!$A:$F,4),"") -> 970432 | I12: https://cdn.vietqr.io/img/VPB.png | J12: =IFERROR(__xludf.DUMMYFUNCTION("""https://img.vietqr.io/image/""&F12&""-""&E12&""-""&FILTER(MauHienThi!$A:$A,MauHienThi!$C:$C=TRUE)&"".png?accountName=""&ENCODEURL(D12)&""&amount="""),"https://img.vietqr.io/image/VPB-01MMTTT0075996061-compact2.png?accountName=MoMo%20-%20TKTH%20Huynh%20Tran%20Tuan%20Kiet&amount=") -> https://img.vietqr.io/image/VPB-01MMTTT0075996061-compact2.png?accountName=MoMo%20-%20TKTH%20Huynh%20Tran%20Tuan%20Kiet&amount= | K12: FALSE | L12: FALSE
A13: 12 | B13: 26 | C13: OCB | D13: Huynh Tran Tuan Kiet | E13: 0582118210 | F13: =IFERROR(VLOOKUP(B13,Banks!$A:$F,3),"") -> OCB | G13: =IFERROR(VLOOKUP(B13,Banks!$A:$F,5),"") -> OCB | H13: =IFERROR(VLOOKUP(B13,Banks!$A:$F,4),"") -> 970448 | I13: https://cdn.vietqr.io/img/VPB.png | J13: =IFERROR(__xludf.DUMMYFUNCTION("""https://img.vietqr.io/image/""&F13&""-""&E13&""-""&FILTER(MauHienThi!$A:$A,MauHienThi!$C:$C=TRUE)&"".png?accountName=""&ENCODEURL(D13)&""&amount="""),"https://img.vietqr.io/image/OCB-0582118210-compact2.png?accountName=Huynh%20Tran%20Tuan%20Kiet&amount=") -> https://img.vietqr.io/image/OCB-0582118210-compact2.png?accountName=Huynh%20Tran%20Tuan%20Kiet&amount= | K13: FALSE | L13: FALSE
F14: =IFERROR(VLOOKUP(B14,Banks!$A:$F,3),"") | G14: =IFERROR(VLOOKUP(B14,Banks!$A:$F,5),"") | H14: =IFERROR(VLOOKUP(B14,Banks!$A:$F,4),"")
F15: =IFERROR(VLOOKUP(B15,Banks!$A:$F,3),"") | G15: =IFERROR(VLOOKUP(B15,Banks!$A:$F,5),"") | H15: =IFERROR(VLOOKUP(B15,Banks!$A:$F,4),"")
F16: =IFERROR(VLOOKUP(B16,Banks!$A:$F,3),"") | G16: =IFERROR(VLOOKUP(B16,Banks!$A:$F,5),"") | H16: =IFERROR(VLOOKUP(B16,Banks!$A:$F,4),"")
F17: =IFERROR(VLOOKUP(B17,Banks!$A:$F,3),"") | G17: =IFERROR(VLOOKUP(B17,Banks!$A:$F,5),"") | H17: =IFERROR(VLOOKUP(B17,Banks!$A:$F,4),"")
F18: =IFERROR(VLOOKUP(B18,Banks!$A:$F,3),"") | G18: =IFERROR(VLOOKUP(B18,Banks!$A:$F,5),"") | H18: =IFERROR(VLOOKUP(B18,Banks!$A:$F,4),"")
F19: =IFERROR(VLOOKUP(B19,Banks!$A:$F,3),"") | G19: =IFERROR(VLOOKUP(B19,Banks!$A:$F,5),"") | H19: =IFERROR(VLOOKUP(B19,Banks!$A:$F,4),"")
F20: =IFERROR(VLOOKUP(B20,Banks!$A:$F,3),"") | G20: =IFERROR(VLOOKUP(B20,Banks!$A:$F,5),"") | H20: =IFERROR(VLOOKUP(B20,Banks!$A:$F,4),"")
J34: =IFERROR(__xludf.DUMMYFUNCTION("FILTER(MauHienThi!$A2:$A1000,MauHienThi!$C2:$C1000=TRUE)"),"compact2") -> compact2

Sheet MauChuyenTien
A1: name | B1: accountName | C1: accountNum | D1: amount | E1: content | F1: template | G1: qr_link
A2: GRAB | B2: GRAB | C2: =IFERROR(VLOOKUP(B2,TaiKhoan!$C:$I,3,0),"") -> 150010000111 | D2: 500000 | E2: 9246061 HUYNH TRAN TUAN KIET | F2: print | G2: =if(A2<>"","https://img.vietqr.io/image/" & VLOOKUP(B2, TaiKhoan!$C:$F, 4, 0) & "-" & C2 & "-" & F2 & ".png?accountName=" & ENCODEURL(VLOOKUP(B2, TaiKhoan!$C:$E, 2, 0)) & "&amount=" & D2&"&addInfo="&ENCODEURL(E2),"") -> https://img.vietqr.io/image/ICB-150010000111-print.png?accountName=CONG%20TY%20TNHH%20GRAB&amount=500000&addInfo=9246061%20HUYNH%20TRAN%20TUAN%20KIET
A3: VIETLOT SMS | B3: Viettel Money | C3: =IFERROR(VLOOKUP(B3,TaiKhoan!$C:$I,3,0),"") -> 9704229201938102578 | D3: 20000 | E3: Tuan Kiet Chuyen Tien | F3: print | G3: =if(A3<>"","https://img.vietqr.io/image/" & VLOOKUP(B3, TaiKhoan!$C:$F, 4, 0) & "-" & C3 & "-" & F3 & ".png?accountName=" & ENCODEURL(VLOOKUP(B3, TaiKhoan!$C:$E, 2, 0)) & "&amount=" & D3&"&addInfo="&ENCODEURL(E3),"") -> https://img.vietqr.io/image/MB-9704229201938102578-print.png?accountName=Huynh%20Tran%20Tuan%20Kiet&amount=20000&addInfo=Tuan%20Kiet%20Chuyen%20Tien
A4: VIetcombank | B4: Vietcombank | C4: =IFERROR(VLOOKUP(B4,TaiKhoan!$C:$I,3,0),"") -> 1031451081 | F4: print | G4: =if(A4<>"","https://img.vietqr.io/image/" & VLOOKUP(B4, TaiKhoan!$C:$F, 4, 0) & "-" & C4 & "-" & F4 & ".png?accountName=" & ENCODEURL(VLOOKUP(B4, TaiKhoan!$C:$E, 2, 0)) & "&amount=" & D4&"&addInfo="&ENCODEURL(E4),"") -> https://img.vietqr.io/image/VCB-1031451081-print.png?accountName=Huynh%20Tran%20Tuan%20Kiet&amount=&addInfo=
C5: =IFERROR(VLOOKUP(B5,TaiKhoan!$C:$I,3,0),"") | G5: =if(A5<>"","https://img.vietqr.io/image/" & VLOOKUP(B5, TaiKhoan!$C:$F, 4, 0) & "-" & C5 & "-" & F5 & ".png?accountName=" & ENCODEURL(VLOOKUP(B5, TaiKhoan!$C:$E, 2, 0)) & "&amount=" & D5&"&addInfo="&ENCODEURL(E5),"")
C6: =IFERROR(VLOOKUP(B6,TaiKhoan!$C:$I,3,0),"") | G6: =if(A6<>"","https://img.vietqr.io/image/" & VLOOKUP(B6, TaiKhoan!$C:$F, 4, 0) & "-" & C6 & "-" & F6 & ".png?accountName=" & ENCODEURL(VLOOKUP(B6, TaiKhoan!$C:$E, 2, 0)) & "&amount=" & D6&"&addInfo="&ENCODEURL(E6),"")
C7: =IFERROR(VLOOKUP(B7,TaiKhoan!$C:$I,3,0),"") | G7: =if(A7<>"","https://img.vietqr.io/image/" & VLOOKUP(B7, TaiKhoan!$C:$F, 4, 0) & "-" & C7 & "-" & F7 & ".png?accountName=" & ENCODEURL(VLOOKUP(B7, TaiKhoan!$C:$E, 2, 0)) & "&amount=" & D7&"&addInfo="&ENCODEURL(E7),"")
C8: =IFERROR(VLOOKUP(B8,TaiKhoan!$C:$I,3,0),"") | G8: =if(A8<>"","https://img.vietqr.io/image/" & VLOOKUP(B8, TaiKhoan!$C:$F, 4, 0) & "-" & C8 & "-" & F8 & ".png?accountName=" & ENCODEURL(VLOOKUP(B8, TaiKhoan!$C:$E, 2, 0)) & "&amount=" & D8&"&addInfo="&ENCODEURL(E8),"")
C9: =IFERROR(VLOOKUP(B9,TaiKhoan!$C:$I,3,0),"") | G9: =if(A9<>"","https://img.vietqr.io/image/" & VLOOKUP(B9, TaiKhoan!$C:$F, 4, 0) & "-" & C9 & "-" & F9 & ".png?accountName=" & ENCODEURL(VLOOKUP(B9, TaiKhoan!$C:$E, 2, 0)) & "&amount=" & D9&"&addInfo="&ENCODEURL(E9),"")
C10: =IFERROR(VLOOKUP(B10,TaiKhoan!$C:$I,3,0),"") | G10: =if(A10<>"","https://img.vietqr.io/image/" & VLOOKUP(B10, TaiKhoan!$C:$F, 4, 0) & "-" & C10 & "-" & F10 & ".png?accountName=" & ENCODEURL(VLOOKUP(B10, TaiKhoan!$C:$E, 2, 0)) & "&amount=" & D10&"&addInfo="&ENCODEURL(E10),"")
C11: =IFERROR(VLOOKUP(B11,TaiKhoan!$C:$I,3,0),"") | G11: =if(A11<>"","https://img.vietqr.io/image/" & VLOOKUP(B11, TaiKhoan!$C:$F, 4, 0) & "-" & C11 & "-" & F11 & ".png?accountName=" & ENCODEURL(VLOOKUP(B11, TaiKhoan!$C:$E, 2, 0)) & "&amount=" & D11&"&addInfo="&ENCODEURL(E11),"")
C12: =IFERROR(VLOOKUP(B12,TaiKhoan!$C:$I,3,0),"") | G12: =if(A12<>"","https://img.vietqr.io/image/" & VLOOKUP(B12, TaiKhoan!$C:$F, 4, 0) & "-" & C12 & "-" & F12 & ".png?accountName=" & ENCODEURL(VLOOKUP(B12, TaiKhoan!$C:$E, 2, 0)) & "&amount=" & D12&"&addInfo="&ENCODEURL(E12),"")
C13: =IFERROR(VLOOKUP(B13,TaiKhoan!$C:$I,3,0),"") | G13: =if(A13<>"","https://img.vietqr.io/image/" & VLOOKUP(B13, TaiKhoan!$C:$F, 4, 0) & "-" & C13 & "-" & F13 & ".png?accountName=" & ENCODEURL(VLOOKUP(B13, TaiKhoan!$C:$E, 2, 0)) & "&amount=" & D13&"&addInfo="&ENCODEURL(E13),"")
C14: =IFERROR(VLOOKUP(B14,TaiKhoan!$C:$I,3,0),"") | G14: =if(A14<>"","https://img.vietqr.io/image/" & VLOOKUP(B14, TaiKhoan!$C:$F, 4, 0) & "-" & C14 & "-" & F14 & ".png?accountName=" & ENCODEURL(VLOOKUP(B14, TaiKhoan!$C:$E, 2, 0)) & "&amount=" & D14&"&addInfo="&ENCODEURL(E14),"")
C15: =IFERROR(VLOOKUP(B15,TaiKhoan!$C:$I,3,0),"") | G15: =if(A15<>"","https://img.vietqr.io/image/" & VLOOKUP(B15, TaiKhoan!$C:$F, 4, 0) & "-" & C15 & "-" & F15 & ".png?accountName=" & ENCODEURL(VLOOKUP(B15, TaiKhoan!$C:$E, 2, 0)) & "&amount=" & D15&"&addInfo="&ENCODEURL(E15),"")
C16: =IFERROR(VLOOKUP(B16,TaiKhoan!$C:$I,3,0),"") | G16: =if(A16<>"","https://img.vietqr.io/image/" & VLOOKUP(B16, TaiKhoan!$C:$F, 4, 0) & "-" & C16 & "-" & F16 & ".png?accountName=" & ENCODEURL(VLOOKUP(B16, TaiKhoan!$C:$E, 2, 0)) & "&amount=" & D16&"&addInfo="&ENCODEURL(E16),"")
... C20: =IFERROR(VLOOKUP(B20,TaiKhoan!$C:$I,3,0),"") | G20: =if(A20<>"","https://img.vietqr.io/image/" & VLOOKUP(B20, TaiKhoan!$C:$F, 4, 0) & "-" & C20 & "-" & F20 & ".png?accountName=" & ENCODEURL(VLOOKUP(B20, TaiKhoan!$C:$E, 2, 0)) & "&amount=" & D20&"&addInfo="&ENCODEURL(E20),"")

Sheet MauHienThi
A1: value | B1: label | C1: default
A2: compact | B2: Compact | C2: FALSE
A3: compact2 | B3: Compact 2 | C3: TRUE
A4: print | B4: Print | C4: FALSE
A5: qr_only | B5: Qr_only | C5: FALSE
A6: BdT8CDO | B6: VietQR plus | C6: FALSE

Sheet Banks
A1: id | B1: name | C1: code | D1: bin | E1: shortName | F1: logo | G1: transferSupported | H1: lookupSupported | I1: short_name | J1: support | K1: isTransfer | L1: swift_code
A2: 1 | B2: Ngân hàng TMCP An Bình | C2: ABB | D2: 970425 | E2: ABBANK | F2: https://cdn.vietqr.io/img/ABB.png | G2: 1 | H2: 1 | I2: ABBANK | J2: 3 | K2: 1 | L2: ABBKVNVX
A3: 2 | B3: Ngân hàng TMCP Á Châu | C3: ACB | D3: 970416 | E3: ACB | F3: https://cdn.vietqr.io/img/ACB.png | G3: 1 | H3: 1 | I3: ACB | J3: 3 | K3: 1 | L3: ASCBVNVX
A4: 3 | B4: Ngân hàng TMCP Bắc Á | C4: BAB | D4: 970409 | E4: BacABank | F4: https://cdn.vietqr.io/img/BAB.png | G4: 1 | H4: 1 | I4: BacABank | J4: 3 | K4: 1 | L4: NASCVNVX
A5: 4 | B5: Ngân hàng TMCP Đầu tư và Phát triển Việt Nam | C5: BIDV | D5: 970418 | E5: BIDV | F5: https://cdn.vietqr.io/img/BIDV.png | G5: 1 | H5: 1 | I5: BIDV | J5: 3 | K5: 1 | L5: BIDVVNVX
A6: 5 | B6: Ngân hàng TMCP Bảo Việt | C6: BVB | D6: 970438 | E6: BaoVietBank | F6: https://cdn.vietqr.io/img/BVB.png | G6: 1 | H6: 1 | I6: BaoVietBank | J6: 3 | K6: 1 | L6: BVBVVNVX
A7: 6 | B7: Ngân hàng Thương mại TNHH MTV Xây dựng Việt Nam | C7: CBB | D7: 970444 | E7: CBBank | F7: https://cdn.vietqr.io/img/CBB.png | G7: 0 | H7: 1 | I7: CBBank | J7: 0 | K7: 0 | L7: GTBAVNVX
A8: 7 | B8: Ngân hàng TNHH MTV CIMB Việt Nam | C8: CIMB | D8: 422589 | E8: CIMB | F8: https://cdn.vietqr.io/img/CIMB.png | G8: 1 | H8: 1 | I8: CIMB | J8: 0 | K8: 1 | L8: CIBBVNVN
A9: 8 | B9: DBS Bank Ltd - Chi nhánh Thành phố Hồ Chí Minh | C9: DBS | D9: 796500 | E9: DBSBank | F9: https://cdn.vietqr.io/img/DBS.png | G9: 0 | H9: 0 | I9: DBSBank | J9: 0 | K9: 0 | L9: DBSSVNVX
A10: 9 | B10: Ngân hàng TNHH MTV Số Vikki | C10: Vikki | D10: 970406 | E10: Vikki | F10: https://cdn.vietqr.io/img/Vikki.png | G10: 0 | H10: 1 | I10: Vikki | J10: 0 | K10: 0 | L10: EACBVNVX
A11: 10 | B11: Ngân hàng TMCP Xuất Nhập khẩu Việt Nam | C11: EIB | D11: 970431 | E11: Eximbank | F11: https://cdn.vietqr.io/img/EIB.png | G11: 1 | H11: 1 | I11: Eximbank | J11: 3 | K11: 1 | L11: EBVIVNVX
A12: 11 | B12: Ngân hàng Thương mại TNHH MTV Dầu Khí Toàn Cầu | C12: GPB | D12: 970408 | E12: GPBank | F12: https://cdn.vietqr.io/img/GPB.png | G12: 0 | H12: 1 | I12: GPBank | J12: 0 | K12: 0 | L12: GBNKVNVX
A13: 12 | B13: Ngân hàng TMCP Phát triển Thành phố Hồ Chí Minh | C13: HDB | D13: 970437 | E13: HDBank | F13: https://cdn.vietqr.io/img/HDB.png | G13: 1 | H13: 1 | I13: HDBank | J13: 3 | K13: 1 | L13: HDBCVNVX
... A15: 14 | B15: Ngân hàng TNHH MTV HSBC (Việt Nam) | C15: HSBC | D15: 458761 | E15: HSBC | F15: https://cdn.vietqr.io/img/HSBC.png | G15: 0 | H15: 1 | I15: HSBC | J15: 0 | K15: 0 | L15: HSBCVNVX
A16: 15 | B16: Ngân hàng Công nghiệp Hàn Quốc - Chi nhánh Hà Nội | C16: IBK - HN | D16: 970455 | E16: IBKHN | F16: https://cdn.vietqr.io/img/IBK.png | G16: 0 | H16: 0 | I16: IBKHN | J16: 0 | K16: 0
A17: 16 | B17: Ngân hàng Công nghiệp Hàn Quốc - Chi nhánh TP. Hồ Chí Minh | C17: IBK - HCM | D17: 970456 | E17: IBKHCM | F17: https://cdn.vietqr.io/img/IBK.png | G17: 0 | H17: 0 | I17: IBKHCM | J17: 0 | K17: 0
A18: 17 | B18: Ngân hàng TMCP Công thương Việt Nam | C18: ICB | D18: 970415 | E18: VietinBank | F18: https://cdn.vietqr.io/img/ICB.png | G18: 1 | H18: 1 | I18: VietinBank | J18: 3 | K18: 1 | L18: ICBVVNVX
A19: 18 | B19: Ngân hàng TNHH Indovina | C19: IVB | D19: 970434 | E19: IndovinaBank | F19: https://cdn.vietqr.io/img/IVB.png | G19: 0 | H19: 1 | I19: IndovinaBank | J19: 0 | K19: 0
A20: 19 | B20: Ngân hàng TMCP Kiên Long | C20: KLB | D20: 970452 | E20: KienLongBank | F20: https://cdn.vietqr.io/img/KLB.png | G20: 1 | H20: 1 | I20: KienLongBank | J20: 3 | K20: 1 | L20: KLBKVNVX
A21: 20 | B21: Ngân hàng TMCP Lộc Phát Việt Nam | C21: LPB | D21: 970449 | E21: LPBank | F21: https://cdn.vietqr.io/img/LPB.png | G21: 1 | H21: 1 | I21: LPBank | J21: 3 | K21: 1 | L21: LVBKVNVX
A22: 21 | B22: Ngân hàng TMCP Quân đội | C22: MB | D22: 970422 | E22: MBBank | F22: https://cdn.vietqr.io/img/MB.png | G22: 1 | H22: 1 | I22: MBBank | J22: 3 | K22: 1 | L22: MSCBVNVX
A23: 22 | B23: Ngân hàng TMCP Hàng Hải Việt Nam | C23: MSB | D23: 970426 | E23: MSB | F23: https://cdn.vietqr.io/img/MSB.png | G23: 1 | H23: 1 | I23: MSB | J23: 3 | K23: 1 | L23: MCOBVNVX
A24: 23 | B24: Ngân hàng TMCP Nam Á | C24: NAB | D24: 970428 | E24: NamABank | F24: https://cdn.vietqr.io/img/NAB.png | G24: 1 | H24: 1 | I24: NamABank | J24: 3 | K24: 1 | L24: NAMAVNVX
A25: 24 | B25: Ngân hàng TMCP Quốc Dân | C25: NCB | D25: 970419 | E25: NCB | F25: https://cdn.vietqr.io/img/NCB.png | G25: 1 | H25: 1 | I25: NCB | J25: 3 | K25: 1 | L25: NVBAVNVX
A26: 25 | B26: Ngân hàng Nonghyup - Chi nhánh Hà Nội | C26: NHB HN | D26: 801011 | E26: Nonghyup | F26: https://cdn.vietqr.io/img/NHB.png | G26: 0 | H26: 0 | I26: Nonghyup | J26: 0 | K26: 0
A27: 26 | B27: Ngân hàng TMCP Phương Đông | C27: OCB | D27: 970448 | E27: OCB | F27: https://cdn.vietqr.io/img/OCB.png | G27: 1 | H27: 1 | I27: OCB | J27: 3 | K27: 1 | L27: ORCOVNVX
A28: 27 | B28: Ngân hàng TNHH MTV Việt Nam Hiện Đại | C28: MBV | D28: 970414 | E28: MBV | F28: https://cdn.vietqr.io/img/MBV.png | G28: 1 | H28: 1 | I28: MBV | J28: 3 | K28: 1 | L28: OCBKUS3M
A29: 28 | B29: Ngân hàng TNHH MTV Public Việt Nam | C29: PBVN | D29: 970439 | E29: PublicBank | F29: https://cdn.vietqr.io/img/PBVN.png | G29: 0 | H29: 1 | I29: PublicBank | J29: 0 | K29: 0 | L29: VIDPVNVX
A30: 29 | B30: Ngân hàng TMCP Thịnh vượng và Phát triển | C30: PGB | D30: 970430 | E30: PGBank | F30: https://cdn.vietqr.io/img/PGB.png | G30: 1 | H30: 1 | I30: PGBank | J30: 3 | K30: 1 | L30: PGBLVNVX
A31: 30 | B31: Ngân hàng TMCP Đại Chúng Việt Nam | C31: PVCB | D31: 970412 | E31: PVcomBank | F31: https://cdn.vietqr.io/img/PVCB.png | G31: 1 | H31: 1 | I31: PVcomBank | J31: 3 | K31: 1 | L31: WBVNVNVX
A32: 31 | B32: Ngân hàng TMCP Sài Gòn | C32: SCB | D32: 970429 | E32: SCB | F32: https://cdn.vietqr.io/img/SCB.png | G32: 1 | H32: 1 | I32: SCB | J32: 3 | K32: 1 | L32: SACLVNVX
A33: 32 | B33: Ngân hàng TNHH MTV Standard Chartered Bank Việt Nam | C33: SCVN | D33: 970410 | E33: StandardChartered | F33: https://cdn.vietqr.io/img/SCVN.png | G33: 0 | H33: 1 | I33: StandardChartered | J33: 0 | K33: 0 | L33: SCBLVNVX
A34: 33 | B34: Ngân hàng TMCP Đông Nam Á | C34: SEAB | D34: 970440 | E34: SeABank | F34: https://cdn.vietqr.io/img/SEAB.png | G34: 1 | H34: 1 | I34: SeABank | J34: 3 | K34: 1 | L34: SEAVVNVX
A35: 34 | B35: Ngân hàng TMCP Sài Gòn Công Thương | C35: SGICB | D35: 970400 | E35: SaigonBank | F35: https://cdn.vietqr.io/img/SGICB.png | G35: 1 | H35: 1 | I35: SaigonBank | J35: 3 | K35: 1 | L35: SBITVNVX
A36: 35 | B36: Ngân hàng TMCP Sài Gòn - Hà Nội | C36: SHB | D36: 970443 | E36: SHB | F36: https://cdn.vietqr.io/img/SHB.png | G36: 1 | H36: 1 | I36: SHB | J36: 3 | K36: 1 | L36: SHBAVNVX
A37: 36 | B37: Ngân hàng TMCP Sài Gòn Thương Tín | C37: STB | D37: 970403 | E37: Sacombank | F37: https://cdn.vietqr.io/img/STB.png | G37: 1 | H37: 1 | I37: Sacombank | J37: 3 | K37: 1 | L37: SGTTVNVX
A38: 37 | B38: Ngân hàng TNHH MTV Shinhan Việt Nam | C38: SHBVN | D38: 970424 | E38: ShinhanBank | F38: https://cdn.vietqr.io/img/SHBVN.png | G38: 1 | H38: 1 | I38: ShinhanBank | J38: 3 | K38: 1 | L38: SHBKVNVX
... A40: 39 | B40: Ngân hàng TMCP Tiên Phong | C40: TPB | D40: 970423 | E40: TPBank | F40: https://cdn.vietqr.io/img/TPB.png | G40: 1 | H40: 1 | I40: TPBank | J40: 3 | K40: 1 | L40: TPBVVNVX
A41: 40 | B41: Ngân hàng United Overseas - Chi nhánh TP. Hồ Chí Minh | C41: UOB | D41: 970458 | E41: UnitedOverseas | F41: https://cdn.vietqr.io/img/UOB.png | G41: 0 | H41: 1 | I41: UnitedOverseas | J41: 0 | K41: 0
A42: 41 | B42: Ngân hàng TMCP Việt Á | C42: VAB | D42: 970427 | E42: VietABank | F42: https://cdn.vietqr.io/img/VAB.png | G42: 1 | H42: 1 | I42: VietABank | J42: 3 | K42: 1 | L42: VNACVNVX
...
